[36m[2023-10-19 19:21:22 DEBUG] [cli:114][39m ###############################################################################
[36m[2023-10-19 19:21:22 DEBUG] [cli:115][39m Running command 'run'
[36m[2023-10-19 19:21:22 DEBUG] [cli:119][39m Using settings file 'C:\Users\blina\.chaostoolkit\settings.yaml'
[36m[2023-10-19 19:21:24 DEBUG] [settings:30][39m The Chaos Toolkit settings file could not be found at 'C:\Users\blina\.chaostoolkit\settings.yaml'.
[36m[2023-10-19 19:21:24 DEBUG] [__init__:445][39m No controls to apply on 'loader'
[36m[2023-10-19 19:21:24 DEBUG] [__init__:445][39m No controls to apply on 'loader'
[36m[2023-10-19 19:21:24 DEBUG] [caching:24][39m Building activity cache...
[36m[2023-10-19 19:21:24 DEBUG] [caching:35][39m Cached 3 activities
[32m[2023-10-19 19:21:24 INFO] [experiment:58][39m Validating the experiment's syntax
[36m[2023-10-19 19:21:24 DEBUG] [configuration:63][39m Loading configuration...
[36m[2023-10-19 19:21:24 DEBUG] [secret:78][39m Loading secrets...
[36m[2023-10-19 19:21:24 DEBUG] [secret:103][39m Done loading secrets
[32m[2023-10-19 19:21:25 INFO] [experiment:109][39m Experiment looks valid
[36m[2023-10-19 19:21:25 DEBUG] [caching:42][39m Clearing activities cache
[36m[2023-10-19 19:21:25 DEBUG] [cli:314][39m Runtime strategies: hypothesis - default / rollbacks - default
[36m[2023-10-19 19:21:25 DEBUG] [caching:24][39m Building activity cache...
[36m[2023-10-19 19:21:25 DEBUG] [caching:35][39m Cached 3 activities
[36m[2023-10-19 19:21:25 DEBUG] [configuration:63][39m Loading configuration...
[36m[2023-10-19 19:21:25 DEBUG] [secret:78][39m Loading secrets...
[36m[2023-10-19 19:21:25 DEBUG] [secret:103][39m Done loading secrets
[36m[2023-10-19 19:21:25 DEBUG] [configuration:160][39m Loading dynamic configuration...
[36m[2023-10-19 19:21:25 DEBUG] [exit:89][39m System 'Windows-10-10.0.19045-SP0' does not expose SIGUSR signals
[32m[2023-10-19 19:21:25 INFO] [run:369][39m Running experiment: My app is resilient to administrative node drainage
[36m[2023-10-19 19:21:25 DEBUG] [__init__:59][39m Initializing controls
[32m[2023-10-19 19:21:25 INFO] [run:396][39m Steady-state strategy: default
[32m[2023-10-19 19:21:25 INFO] [run:400][39m Rollbacks strategy: default
[36m[2023-10-19 19:21:25 DEBUG] [__init__:445][39m No controls to apply on 'experiment'
[36m[2023-10-19 19:21:25 DEBUG] [run:563][39m Running steady-state hypothesis before the method
[32m[2023-10-19 19:21:25 INFO] [hypothesis:186][39m Steady state hypothesis: Services available and healthy
[36m[2023-10-19 19:21:25 DEBUG] [__init__:445][39m No controls to apply on 'hypothesis'
[36m[2023-10-19 19:21:25 DEBUG] [__init__:445][39m No controls to apply on 'activity'
[32m[2023-10-19 19:21:25 INFO] [activity:215][39m Probe: application-must-respond-normally
[36m[2023-10-19 19:21:27 DEBUG] [activity:294][39m Activity failed
    Traceback (most recent call last):
      File "C:\Users\blina\AppData\Local\Programs\Python\Python310\lib\site-packages\urllib3\connection.py", line 174, in _new_conn
        conn = connection.create_connection(
      File "C:\Users\blina\AppData\Local\Programs\Python\Python310\lib\site-packages\urllib3\util\connection.py", line 72, in create_connection
        for res in socket.getaddrinfo(host, port, family, socket.SOCK_STREAM):
      File "C:\Users\blina\AppData\Local\Programs\Python\Python310\lib\socket.py", line 955, in getaddrinfo
        for res in _socket.getaddrinfo(host, port, family, type, proto, flags):
    socket.gaierror: [Errno 11001] getaddrinfo failed
    
    During handling of the above exception, another exception occurred:
    
    Traceback (most recent call last):
      File "C:\Users\blina\AppData\Local\Programs\Python\Python310\lib\site-packages\urllib3\connectionpool.py", line 715, in urlopen
        httplib_response = self._make_request(
      File "C:\Users\blina\AppData\Local\Programs\Python\Python310\lib\site-packages\urllib3\connectionpool.py", line 416, in _make_request
        conn.request(method, url, **httplib_request_kw)
      File "C:\Users\blina\AppData\Local\Programs\Python\Python310\lib\site-packages\urllib3\connection.py", line 244, in request
        super(HTTPConnection, self).request(method, url, body=body, headers=headers)
      File "C:\Users\blina\AppData\Local\Programs\Python\Python310\lib\http\client.py", line 1282, in request
        self._send_request(method, url, body, headers, encode_chunked)
      File "C:\Users\blina\AppData\Local\Programs\Python\Python310\lib\http\client.py", line 1328, in _send_request
        self.endheaders(body, encode_chunked=encode_chunked)
      File "C:\Users\blina\AppData\Local\Programs\Python\Python310\lib\http\client.py", line 1277, in endheaders
        self._send_output(message_body, encode_chunked=encode_chunked)
      File "C:\Users\blina\AppData\Local\Programs\Python\Python310\lib\http\client.py", line 1037, in _send_output
        self.send(msg)
      File "C:\Users\blina\AppData\Local\Programs\Python\Python310\lib\http\client.py", line 975, in send
        self.connect()
      File "C:\Users\blina\AppData\Local\Programs\Python\Python310\lib\site-packages\urllib3\connection.py", line 205, in connect
        conn = self._new_conn()
      File "C:\Users\blina\AppData\Local\Programs\Python\Python310\lib\site-packages\urllib3\connection.py", line 186, in _new_conn
        raise NewConnectionError(
    urllib3.exceptions.NewConnectionError: <urllib3.connection.HTTPConnection object at 0x0000026D3781FB50>: Failed to establish a new connection: [Errno 11001] getaddrinfo failed
    
    During handling of the above exception, another exception occurred:
    
    Traceback (most recent call last):
      File "C:\Users\blina\AppData\Local\Programs\Python\Python310\lib\site-packages\requests\adapters.py", line 486, in send
        resp = conn.urlopen(
      File "C:\Users\blina\AppData\Local\Programs\Python\Python310\lib\site-packages\urllib3\connectionpool.py", line 799, in urlopen
        retries = retries.increment(
      File "C:\Users\blina\AppData\Local\Programs\Python\Python310\lib\site-packages\urllib3\util\retry.py", line 592, in increment
        raise MaxRetryError(_pool, url, error or ResponseError(cause))
    urllib3.exceptions.MaxRetryError: HTTPConnectionPool(host='http', port=80): Max retries exceeded with url: //35.147.81.231/ (Caused by NewConnectionError('<urllib3.connection.HTTPConnection object at 0x0000026D3781FB50>: Failed to establish a new connection: [Errno 11001] getaddrinfo failed'))
    
    During handling of the above exception, another exception occurred:
    
    Traceback (most recent call last):
      File "C:\Users\blina\AppData\Local\Programs\Python\Python310\lib\site-packages\chaoslib\provider\http.py", line 50, in run_http_activity
        r = s.get(
      File "C:\Users\blina\AppData\Local\Programs\Python\Python310\lib\site-packages\requests\sessions.py", line 602, in get
        return self.request("GET", url, **kwargs)
      File "C:\Users\blina\AppData\Local\Programs\Python\Python310\lib\site-packages\requests\sessions.py", line 589, in request
        resp = self.send(prep, **send_kwargs)
      File "C:\Users\blina\AppData\Local\Programs\Python\Python310\lib\site-packages\requests\sessions.py", line 703, in send
        r = adapter.send(request, **kwargs)
      File "C:\Users\blina\AppData\Local\Programs\Python\Python310\lib\site-packages\requests\adapters.py", line 519, in send
        raise ConnectionError(e, request=request)
    requests.exceptions.ConnectionError: HTTPConnectionPool(host='http', port=80): Max retries exceeded with url: //35.147.81.231/ (Caused by NewConnectionError('<urllib3.connection.HTTPConnection object at 0x0000026D3781FB50>: Failed to establish a new connection: [Errno 11001] getaddrinfo failed'))
    
    During handling of the above exception, another exception occurred:
    
    Traceback (most recent call last):
      File "C:\Users\blina\AppData\Local\Programs\Python\Python310\lib\site-packages\chaoslib\activity.py", line 291, in run_activity
        result = run_http_activity(activity, configuration, secrets)
      File "C:\Users\blina\AppData\Local\Programs\Python\Python310\lib\site-packages\chaoslib\provider\http.py", line 96, in run_http_activity
        raise ActivityFailed(f"failed to connect to {url}: {str(cex)}")
    chaoslib.exceptions.ActivityFailed: failed to connect to http://http://35.147.81.231/: HTTPConnectionPool(host='http', port=80): Max retries exceeded with url: //35.147.81.231/ (Caused by NewConnectionError('<urllib3.connection.HTTPConnection object at 0x0000026D3781FB50>: Failed to establish a new connection: [Errno 11001] getaddrinfo failed'))
[31m[2023-10-19 19:21:27 ERROR] [activity:245][39m   => failed: failed to connect to http://http://35.147.81.231/: HTTPConnectionPool(host='http', port=80): Max retries exceeded with url: //35.147.81.231/ (Caused by NewConnectionError('<urllib3.connection.HTTPConnection object at 0x0000026D3781FB50>: Failed to establish a new connection: [Errno 11001] getaddrinfo failed'))
[36m[2023-10-19 19:21:27 DEBUG] [__init__:445][39m No controls to apply on 'activity'
[33m[2023-10-19 19:21:27 WARNING] [hypothesis:213][39m Probe terminated unexpectedly, so its tolerance could not be validated
[36m[2023-10-19 19:21:27 DEBUG] [__init__:445][39m No controls to apply on 'hypothesis'
[31m[2023-10-19 19:21:27 CRITICAL] [run:579][39m Steady state probe 'application-must-respond-normally' is not in the given tolerance so failing this experiment
[32m[2023-10-19 19:21:27 INFO] [run:515][39m Experiment ended with status: failed
[36m[2023-10-19 19:21:27 DEBUG] [__init__:445][39m No controls to apply on 'experiment'
[36m[2023-10-19 19:21:27 DEBUG] [__init__:98][39m Cleaning up controls
[36m[2023-10-19 19:21:27 DEBUG] [caching:42][39m Clearing activities cache
[36m[2023-10-19 19:54:09 DEBUG] [cli:114][39m ###############################################################################
[36m[2023-10-19 19:54:09 DEBUG] [cli:115][39m Running command 'run'
[36m[2023-10-19 19:54:09 DEBUG] [cli:119][39m Using settings file 'C:\Users\blina\.chaostoolkit\settings.yaml'
[36m[2023-10-19 19:54:10 DEBUG] [settings:30][39m The Chaos Toolkit settings file could not be found at 'C:\Users\blina\.chaostoolkit\settings.yaml'.
[36m[2023-10-19 19:54:10 DEBUG] [__init__:445][39m No controls to apply on 'loader'
[36m[2023-10-19 19:54:10 DEBUG] [__init__:445][39m No controls to apply on 'loader'
[36m[2023-10-19 19:54:10 DEBUG] [caching:24][39m Building activity cache...
[36m[2023-10-19 19:54:10 DEBUG] [caching:35][39m Cached 3 activities
[32m[2023-10-19 19:54:10 INFO] [experiment:58][39m Validating the experiment's syntax
[36m[2023-10-19 19:54:10 DEBUG] [configuration:63][39m Loading configuration...
[36m[2023-10-19 19:54:10 DEBUG] [secret:78][39m Loading secrets...
[36m[2023-10-19 19:54:10 DEBUG] [secret:103][39m Done loading secrets
[32m[2023-10-19 19:54:11 INFO] [experiment:109][39m Experiment looks valid
[36m[2023-10-19 19:54:11 DEBUG] [caching:42][39m Clearing activities cache
[36m[2023-10-19 19:54:11 DEBUG] [cli:314][39m Runtime strategies: hypothesis - default / rollbacks - default
[36m[2023-10-19 19:54:11 DEBUG] [caching:24][39m Building activity cache...
[36m[2023-10-19 19:54:11 DEBUG] [caching:35][39m Cached 3 activities
[36m[2023-10-19 19:54:11 DEBUG] [configuration:63][39m Loading configuration...
[36m[2023-10-19 19:54:11 DEBUG] [secret:78][39m Loading secrets...
[36m[2023-10-19 19:54:11 DEBUG] [secret:103][39m Done loading secrets
[36m[2023-10-19 19:54:11 DEBUG] [configuration:160][39m Loading dynamic configuration...
[36m[2023-10-19 19:54:11 DEBUG] [exit:89][39m System 'Windows-10-10.0.19045-SP0' does not expose SIGUSR signals
[32m[2023-10-19 19:54:11 INFO] [run:369][39m Running experiment: My app is resilient to administrative node drainage
[36m[2023-10-19 19:54:11 DEBUG] [__init__:59][39m Initializing controls
[32m[2023-10-19 19:54:11 INFO] [run:396][39m Steady-state strategy: default
[32m[2023-10-19 19:54:11 INFO] [run:400][39m Rollbacks strategy: default
[36m[2023-10-19 19:54:11 DEBUG] [__init__:445][39m No controls to apply on 'experiment'
[36m[2023-10-19 19:54:11 DEBUG] [run:563][39m Running steady-state hypothesis before the method
[32m[2023-10-19 19:54:11 INFO] [hypothesis:186][39m Steady state hypothesis: Services available and healthy
[36m[2023-10-19 19:54:11 DEBUG] [__init__:445][39m No controls to apply on 'hypothesis'
[36m[2023-10-19 19:54:11 DEBUG] [__init__:445][39m No controls to apply on 'activity'
[32m[2023-10-19 19:54:11 INFO] [activity:215][39m Probe: application-must-respond-normally
[36m[2023-10-19 19:54:13 DEBUG] [activity:294][39m Activity failed
    Traceback (most recent call last):
      File "C:\Users\blina\AppData\Local\Programs\Python\Python310\lib\site-packages\urllib3\connection.py", line 174, in _new_conn
        conn = connection.create_connection(
      File "C:\Users\blina\AppData\Local\Programs\Python\Python310\lib\site-packages\urllib3\util\connection.py", line 72, in create_connection
        for res in socket.getaddrinfo(host, port, family, socket.SOCK_STREAM):
      File "C:\Users\blina\AppData\Local\Programs\Python\Python310\lib\socket.py", line 955, in getaddrinfo
        for res in _socket.getaddrinfo(host, port, family, type, proto, flags):
    socket.gaierror: [Errno 11001] getaddrinfo failed
    
    During handling of the above exception, another exception occurred:
    
    Traceback (most recent call last):
      File "C:\Users\blina\AppData\Local\Programs\Python\Python310\lib\site-packages\urllib3\connectionpool.py", line 715, in urlopen
        httplib_response = self._make_request(
      File "C:\Users\blina\AppData\Local\Programs\Python\Python310\lib\site-packages\urllib3\connectionpool.py", line 416, in _make_request
        conn.request(method, url, **httplib_request_kw)
      File "C:\Users\blina\AppData\Local\Programs\Python\Python310\lib\site-packages\urllib3\connection.py", line 244, in request
        super(HTTPConnection, self).request(method, url, body=body, headers=headers)
      File "C:\Users\blina\AppData\Local\Programs\Python\Python310\lib\http\client.py", line 1282, in request
        self._send_request(method, url, body, headers, encode_chunked)
      File "C:\Users\blina\AppData\Local\Programs\Python\Python310\lib\http\client.py", line 1328, in _send_request
        self.endheaders(body, encode_chunked=encode_chunked)
      File "C:\Users\blina\AppData\Local\Programs\Python\Python310\lib\http\client.py", line 1277, in endheaders
        self._send_output(message_body, encode_chunked=encode_chunked)
      File "C:\Users\blina\AppData\Local\Programs\Python\Python310\lib\http\client.py", line 1037, in _send_output
        self.send(msg)
      File "C:\Users\blina\AppData\Local\Programs\Python\Python310\lib\http\client.py", line 975, in send
        self.connect()
      File "C:\Users\blina\AppData\Local\Programs\Python\Python310\lib\site-packages\urllib3\connection.py", line 205, in connect
        conn = self._new_conn()
      File "C:\Users\blina\AppData\Local\Programs\Python\Python310\lib\site-packages\urllib3\connection.py", line 186, in _new_conn
        raise NewConnectionError(
    urllib3.exceptions.NewConnectionError: <urllib3.connection.HTTPConnection object at 0x000002353D7AD180>: Failed to establish a new connection: [Errno 11001] getaddrinfo failed
    
    During handling of the above exception, another exception occurred:
    
    Traceback (most recent call last):
      File "C:\Users\blina\AppData\Local\Programs\Python\Python310\lib\site-packages\requests\adapters.py", line 486, in send
        resp = conn.urlopen(
      File "C:\Users\blina\AppData\Local\Programs\Python\Python310\lib\site-packages\urllib3\connectionpool.py", line 799, in urlopen
        retries = retries.increment(
      File "C:\Users\blina\AppData\Local\Programs\Python\Python310\lib\site-packages\urllib3\util\retry.py", line 592, in increment
        raise MaxRetryError(_pool, url, error or ResponseError(cause))
    urllib3.exceptions.MaxRetryError: HTTPConnectionPool(host='http', port=80): Max retries exceeded with url: //35.147.81.231/ (Caused by NewConnectionError('<urllib3.connection.HTTPConnection object at 0x000002353D7AD180>: Failed to establish a new connection: [Errno 11001] getaddrinfo failed'))
    
    During handling of the above exception, another exception occurred:
    
    Traceback (most recent call last):
      File "C:\Users\blina\AppData\Local\Programs\Python\Python310\lib\site-packages\chaoslib\provider\http.py", line 50, in run_http_activity
        r = s.get(
      File "C:\Users\blina\AppData\Local\Programs\Python\Python310\lib\site-packages\requests\sessions.py", line 602, in get
        return self.request("GET", url, **kwargs)
      File "C:\Users\blina\AppData\Local\Programs\Python\Python310\lib\site-packages\requests\sessions.py", line 589, in request
        resp = self.send(prep, **send_kwargs)
      File "C:\Users\blina\AppData\Local\Programs\Python\Python310\lib\site-packages\requests\sessions.py", line 703, in send
        r = adapter.send(request, **kwargs)
      File "C:\Users\blina\AppData\Local\Programs\Python\Python310\lib\site-packages\requests\adapters.py", line 519, in send
        raise ConnectionError(e, request=request)
    requests.exceptions.ConnectionError: HTTPConnectionPool(host='http', port=80): Max retries exceeded with url: //35.147.81.231/ (Caused by NewConnectionError('<urllib3.connection.HTTPConnection object at 0x000002353D7AD180>: Failed to establish a new connection: [Errno 11001] getaddrinfo failed'))
    
    During handling of the above exception, another exception occurred:
    
    Traceback (most recent call last):
      File "C:\Users\blina\AppData\Local\Programs\Python\Python310\lib\site-packages\chaoslib\activity.py", line 291, in run_activity
        result = run_http_activity(activity, configuration, secrets)
      File "C:\Users\blina\AppData\Local\Programs\Python\Python310\lib\site-packages\chaoslib\provider\http.py", line 96, in run_http_activity
        raise ActivityFailed(f"failed to connect to {url}: {str(cex)}")
    chaoslib.exceptions.ActivityFailed: failed to connect to http://http://35.147.81.231/: HTTPConnectionPool(host='http', port=80): Max retries exceeded with url: //35.147.81.231/ (Caused by NewConnectionError('<urllib3.connection.HTTPConnection object at 0x000002353D7AD180>: Failed to establish a new connection: [Errno 11001] getaddrinfo failed'))
[31m[2023-10-19 19:54:13 ERROR] [activity:245][39m   => failed: failed to connect to http://http://35.147.81.231/: HTTPConnectionPool(host='http', port=80): Max retries exceeded with url: //35.147.81.231/ (Caused by NewConnectionError('<urllib3.connection.HTTPConnection object at 0x000002353D7AD180>: Failed to establish a new connection: [Errno 11001] getaddrinfo failed'))
[36m[2023-10-19 19:54:13 DEBUG] [__init__:445][39m No controls to apply on 'activity'
[33m[2023-10-19 19:54:13 WARNING] [hypothesis:213][39m Probe terminated unexpectedly, so its tolerance could not be validated
[36m[2023-10-19 19:54:13 DEBUG] [__init__:445][39m No controls to apply on 'hypothesis'
[31m[2023-10-19 19:54:13 CRITICAL] [run:579][39m Steady state probe 'application-must-respond-normally' is not in the given tolerance so failing this experiment
[32m[2023-10-19 19:54:13 INFO] [run:515][39m Experiment ended with status: failed
[36m[2023-10-19 19:54:13 DEBUG] [__init__:445][39m No controls to apply on 'experiment'
[36m[2023-10-19 19:54:13 DEBUG] [__init__:98][39m Cleaning up controls
[36m[2023-10-19 19:54:13 DEBUG] [caching:42][39m Clearing activities cache
